Workbook

Sheet LATAM
B1: Male | D1: Female | F1: Total | J1: Significance per country
B2: % | C2: Sd | D2: % | E2: Sd | F2: % | G2: Sd | H2: Test | I2: p-value | J2: Argentina | K2: Bolivia | L2: Brazil | M2: Chile | N2: Colombia | O2: Ecuador | P2: Guatemala | Q2: México | R2: Nicaragua | S2: Peru | T2: Puerto Rico | U2: Uruguay | V2: Venezuela
A3: N | B3: 3494 | C3: 0.47563 | D3: 3852 | E3: 0.52437 | F3: 7346 | G3: 1 | J3: =_xlfn.IFNA(VLOOKUP($A4,Argentina!$A:$I,9,FALSE)," ") | K3: =_xlfn.IFNA(VLOOKUP($A4,Bolivia!$A:$I,9,FALSE)," ") | L3: =_xlfn.IFNA(VLOOKUP($A4,Brazil!$A:$I,9,FALSE)," ") | M3: =_xlfn.IFNA(VLOOKUP($A4,Chile!$A:$I,9,FALSE)," ") | N3: =_xlfn.IFNA(VLOOKUP($A4,Colombia!$A:$I,9,FALSE)," ") -> *** | O3: =_xlfn.IFNA(VLOOKUP($A4,Ecuador!$A:$I,9,FALSE)," ") | P3: =_xlfn.IFNA(VLOOKUP($A4,Guatemala!$A:$I,9,FALSE)," ") | Q3: =_xlfn.IFNA(VLOOKUP($A4,Mexico!$A:$I,9,FALSE)," ") | R3: =_xlfn.IFNA(VLOOKUP($A4,Nicaragua!$A:$I,9,FALSE)," ") | S3: =_xlfn.IFNA(VLOOKUP($A4,Peru!$A:$I,9,FALSE)," ") | T3: =_xlfn.IFNA(VLOOKUP($A4,PuertoRico!$A:$I,9,FALSE)," ") | U3: =_xlfn.IFNA(VLOOKUP($A4,Uruguay!$A:$I,9,FALSE)," ") | V3: =_xlfn.IFNA(VLOOKUP($A4,Venezuela!$A:$I,9,FALSE)," ")
A4: (B) Political action: attending lawful/peaceful demonstrations | B4: 0.828 | C4: 0.377 | D4: 0.849 | E4: 0.358 | F4: 0.839 | G4: 0.368 | H4: 0.015 | I4: =IF(H4>0.1,"", IF(AND(H4<=0.1,H4>0.05),"*", IF(AND(H4<=0.05,H4>0.01),"**", IF(H4<=0.01,"***","")))) -> ** | J4: =_xlfn.IFNA(VLOOKUP(A5,Argentina!A:I,9,FALSE)," ") | K4: =_xlfn.IFNA(VLOOKUP($A5,Bolivia!$A:$I,9,FALSE)," ") | L4: =_xlfn.IFNA(VLOOKUP($A5,Brazil!$A:$I,9,FALSE)," ") | M4: =_xlfn.IFNA(VLOOKUP($A5,Chile!$A:$I,9,FALSE)," ") | N4: =_xlfn.IFNA(VLOOKUP($A5,Colombia!$A:$I,9,FALSE)," ") | O4: =_xlfn.IFNA(VLOOKUP($A5,Ecuador!$A:$I,9,FALSE)," ") -> ** | P4: =_xlfn.IFNA(VLOOKUP($A5,Guatemala!$A:$I,9,FALSE)," ") -> *** | Q4: =_xlfn.IFNA(VLOOKUP($A5,Mexico!$A:$I,9,FALSE)," ") | R4: =_xlfn.IFNA(VLOOKUP($A5,Nicaragua!$A:$I,9,FALSE)," ") | S4: =_xlfn.IFNA(VLOOKUP($A5,Peru!$A:$I,9,FALSE)," ") | T4: =_xlfn.IFNA(VLOOKUP($A5,PuertoRico!$A:$I,9,FALSE)," ") | U4: =_xlfn.IFNA(VLOOKUP($A5,Uruguay!$A:$I,9,FALSE)," ") | V4: =_xlfn.IFNA(VLOOKUP($A5,Venezuela!$A:$I,9,FALSE)," ")
A5: (B) Political action: Signing a petition | B5: 0.796 | C5: 0.403 | D5: 0.807 | E5: 0.395 | F5: 0.802 | G5: 0.398 | H5: 0.249 | I5: =IF(H5>0.1,"", IF(AND(H5<=0.1,H5>0.05),"*", IF(AND(H5<=0.05,H5>0.01),"**", IF(H5<=0.01,"***","")))) | J5: =_xlfn.IFNA(VLOOKUP(A6,Argentina!A:I,9,FALSE)," ") | K5: =_xlfn.IFNA(VLOOKUP($A6,Bolivia!$A:$I,9,FALSE)," ") | L5: =_xlfn.IFNA(VLOOKUP($A6,Brazil!$A:$I,9,FALSE)," ") | M5: =_xlfn.IFNA(VLOOKUP($A6,Chile!$A:$I,9,FALSE)," ") | N5: =_xlfn.IFNA(VLOOKUP($A6,Colombia!$A:$I,9,FALSE)," ") -> ** | O5: =_xlfn.IFNA(VLOOKUP($A6,Ecuador!$A:$I,9,FALSE)," ") | P5: =_xlfn.IFNA(VLOOKUP($A6,Guatemala!$A:$I,9,FALSE)," ") | Q5: =_xlfn.IFNA(VLOOKUP($A6,Mexico!$A:$I,9,FALSE)," ") -> * | R5: =_xlfn.IFNA(VLOOKUP($A6,Nicaragua!$A:$I,9,FALSE)," ") | S5: =_xlfn.IFNA(VLOOKUP($A6,Peru!$A:$I,9,FALSE)," ") | T5: =_xlfn.IFNA(VLOOKUP($A6,PuertoRico!$A:$I,9,FALSE)," ") | U5: =_xlfn.IFNA(VLOOKUP($A6,Uruguay!$A:$I,9,FALSE)," ") | V5: =_xlfn.IFNA(VLOOKUP($A6,Venezuela!$A:$I,9,FALSE)," ")
A6: (B) Political action: joining in boycotts | B6: 0.926 | C6: 0.262 | D6: 0.942 | E6: 0.234 | F6: 0.934 | G6: 0.248 | H6: 0.006 | I6: =IF(H6>0.1,"", IF(AND(H6<=0.1,H6>0.05),"*", IF(AND(H6<=0.05,H6>0.01),"**", IF(H6<=0.01,"***","")))) -> *** | J6: =_xlfn.IFNA(VLOOKUP(A7,Argentina!A:I,9,FALSE)," ") | K6: =_xlfn.IFNA(VLOOKUP($A7,Bolivia!$A:$I,9,FALSE)," ") -> *** | L6: =_xlfn.IFNA(VLOOKUP($A7,Brazil!$A:$I,9,FALSE)," ") | M6: =_xlfn.IFNA(VLOOKUP($A7,Chile!$A:$I,9,FALSE)," ") | N6: =_xlfn.IFNA(VLOOKUP($A7,Colombia!$A:$I,9,FALSE)," ") | O6: =_xlfn.IFNA(VLOOKUP($A7,Ecuador!$A:$I,9,FALSE)," ") -> *** | P6: =_xlfn.IFNA(VLOOKUP($A7,Guatemala!$A:$I,9,FALSE)," ") | Q6: =_xlfn.IFNA(VLOOKUP($A7,Mexico!$A:$I,9,FALSE)," ") | R6: =_xlfn.IFNA(VLOOKUP($A7,Nicaragua!$A:$I,9,FALSE)," ") | S6: =_xlfn.IFNA(VLOOKUP($A7,Peru!$A:$I,9,FALSE)," ") | T6: =_xlfn.IFNA(VLOOKUP($A7,PuertoRico!$A:$I,9,FALSE)," ") | U6: =_xlfn.IFNA(VLOOKUP($A7,Uruguay!$A:$I,9,FALSE)," ") | V6: =_xlfn.IFNA(VLOOKUP($A7,Venezuela!$A:$I,9,FALSE)," ")
A7: (B) Active/Inactive membership: Political party | B7: 0.149 | C7: 0.356 | D7: 0.127 | E7: 0.333 | F7: 0.138 | G7: 0.345 | H7: 0.007 | I7: =IF(H7>0.1,"", IF(AND(H7<=0.1,H7>0.05),"*", IF(AND(H7<=0.05,H7>0.01),"**", IF(H7<=0.01,"***","")))) -> *** | J7: =_xlfn.IFNA(VLOOKUP(A8,Argentina!A:I,9,FALSE)," ") | K7: =_xlfn.IFNA(VLOOKUP($A8,Bolivia!$A:$I,9,FALSE)," ") | L7: =_xlfn.IFNA(VLOOKUP($A8,Brazil!$A:$I,9,FALSE)," ") | M7: =_xlfn.IFNA(VLOOKUP($A8,Chile!$A:$I,9,FALSE)," ") | N7: =_xlfn.IFNA(VLOOKUP($A8,Colombia!$A:$I,9,FALSE)," ") -> * | O7: =_xlfn.IFNA(VLOOKUP($A8,Ecuador!$A:$I,9,FALSE)," ") | P7: =_xlfn.IFNA(VLOOKUP($A8,Guatemala!$A:$I,9,FALSE)," ") | Q7: =_xlfn.IFNA(VLOOKUP($A8,Mexico!$A:$I,9,FALSE)," ") | R7: =_xlfn.IFNA(VLOOKUP($A8,Nicaragua!$A:$I,9,FALSE)," ") | S7: =_xlfn.IFNA(VLOOKUP($A8,Peru!$A:$I,9,FALSE)," ") | T7: =_xlfn.IFNA(VLOOKUP($A8,PuertoRico!$A:$I,9,FALSE)," ") | U7: =_xlfn.IFNA(VLOOKUP($A8,Uruguay!$A:$I,9,FALSE)," ") | V7: =_xlfn.IFNA(VLOOKUP($A8,Venezuela!$A:$I,9,FALSE)," ")
A8: (B) Social activism: Contacting a government official | B8: 0.841 | C8: 0.366 | D8: 0.824 | E8: 0.381 | F8: 0.832 | G8: 0.374 | H8: 0.059 | I8: =IF(H8>0.1,"", IF(AND(H8<=0.1,H8>0.05),"*", IF(AND(H8<=0.05,H8>0.01),"**", IF(H8<=0.01,"***","")))) -> * | J8: =_xlfn.IFNA(VLOOKUP(A9,Argentina!A:I,9,FALSE)," ") | K8: =_xlfn.IFNA(VLOOKUP($A9,Bolivia!$A:$I,9,FALSE)," ") -> ** | L8: =_xlfn.IFNA(VLOOKUP($A9,Brazil!$A:$I,9,FALSE)," ") -> * | M8: =_xlfn.IFNA(VLOOKUP($A9,Chile!$A:$I,9,FALSE)," ") -> * | N8: =_xlfn.IFNA(VLOOKUP($A9,Colombia!$A:$I,9,FALSE)," ") | O8: =_xlfn.IFNA(VLOOKUP($A9,Ecuador!$A:$I,9,FALSE)," ") | P8: =_xlfn.IFNA(VLOOKUP($A9,Guatemala!$A:$I,9,FALSE)," ") -> ** | Q8: =_xlfn.IFNA(VLOOKUP($A9,Mexico!$A:$I,9,FALSE)," ") | R8: =_xlfn.IFNA(VLOOKUP($A9,Nicaragua!$A:$I,9,FALSE)," ") | S8: =_xlfn.IFNA(VLOOKUP($A9,Peru!$A:$I,9,FALSE)," ") | T8: =_xlfn.IFNA(VLOOKUP($A9,PuertoRico!$A:$I,9,FALSE)," ") | U8: =_xlfn.IFNA(VLOOKUP($A9,Uruguay!$A:$I,9,FALSE)," ") | V8: =_xlfn.IFNA(VLOOKUP($A9,Venezuela!$A:$I,9,FALSE)," ")
A9: (B) Social activism: Donating to a group or campaign | B9: 0.655 | C9: 0.475 | D9: 0.652 | E9: 0.476 | F9: 0.653 | G9: 0.476 | H9: 0.774 | I9: =IF(H9>0.1,"", IF(AND(H9<=0.1,H9>0.05),"*", IF(AND(H9<=0.05,H9>0.01),"**", IF(H9<=0.01,"***","")))) | J9: =_xlfn.IFNA(VLOOKUP(A10,Argentina!A:I,9,FALSE)," ") | K9: =_xlfn.IFNA(VLOOKUP($A10,Bolivia!$A:$I,9,FALSE)," ") -> * | L9: =_xlfn.IFNA(VLOOKUP($A10,Brazil!$A:$I,9,FALSE)," ") -> *** | M9: =_xlfn.IFNA(VLOOKUP($A10,Chile!$A:$I,9,FALSE)," ") | N9: =_xlfn.IFNA(VLOOKUP($A10,Colombia!$A:$I,9,FALSE)," ") | O9: =_xlfn.IFNA(VLOOKUP($A10,Ecuador!$A:$I,9,FALSE)," ") -> * | P9: =_xlfn.IFNA(VLOOKUP($A10,Guatemala!$A:$I,9,FALSE)," ") -> * | Q9: =_xlfn.IFNA(VLOOKUP($A10,Mexico!$A:$I,9,FALSE)," ") | R9: =_xlfn.IFNA(VLOOKUP($A10,Nicaragua!$A:$I,9,FALSE)," ") | S9: =_xlfn.IFNA(VLOOKUP($A10,Peru!$A:$I,9,FALSE)," ") | T9: =_xlfn.IFNA(VLOOKUP($A10,PuertoRico!$A:$I,9,FALSE)," ") | U9: =_xlfn.IFNA(VLOOKUP($A10,Uruguay!$A:$I,9,FALSE)," ") | V9: =_xlfn.IFNA(VLOOKUP($A10,Venezuela!$A:$I,9,FALSE)," ")
A10: (B) Social activism: Encouraging others to take action | B10: 0.887 | C10: 0.317 | D10: 0.906 | E10: 0.292 | F10: 0.897 | G10: 0.304 | H10: 0.007 | I10: =IF(H10>0.1,"", IF(AND(H10<=0.1,H10>0.05),"*", IF(AND(H10<=0.05,H10>0.01),"**", IF(H10<=0.01,"***","")))) -> *** | J10: =_xlfn.IFNA(VLOOKUP(A11,Argentina!A:I,9,FALSE)," ") | K10: =_xlfn.IFNA(VLOOKUP($A11,Bolivia!$A:$I,9,FALSE)," ") | L10: =_xlfn.IFNA(VLOOKUP($A11,Brazil!$A:$I,9,FALSE)," ") | M10: =_xlfn.IFNA(VLOOKUP($A11,Chile!$A:$I,9,FALSE)," ") | N10: =_xlfn.IFNA(VLOOKUP($A11,Colombia!$A:$I,9,FALSE)," ") -> ** | O10: =_xlfn.IFNA(VLOOKUP($A11,Ecuador!$A:$I,9,FALSE)," ") | P10: =_xlfn.IFNA(VLOOKUP($A11,Guatemala!$A:$I,9,FALSE)," ") | Q10: =_xlfn.IFNA(VLOOKUP($A11,Mexico!$A:$I,9,FALSE)," ") -> * | R10: =_xlfn.IFNA(VLOOKUP($A11,Nicaragua!$A:$I,9,FALSE)," ") | S10: =_xlfn.IFNA(VLOOKUP($A11,Peru!$A:$I,9,FALSE)," ") | T10: =_xlfn.IFNA(VLOOKUP($A11,PuertoRico!$A:$I,9,FALSE)," ") | U10: =_xlfn.IFNA(VLOOKUP($A11,Uruguay!$A:$I,9,FALSE)," ") | V10: =_xlfn.IFNA(VLOOKUP($A11,Venezuela!$A:$I,9,FALSE)," ")
A11: (B) Political action: joining unofficial strikes | B11: 0.885 | C11: 0.319 | D11: 0.905 | E11: 0.294 | F11: 0.895 | G11: 0.306 | H11: 0.008 | I11: =IF(H11>0.1,"", IF(AND(H11<=0.1,H11>0.05),"*", IF(AND(H11<=0.05,H11>0.01),"**", IF(H11<=0.01,"***","")))) -> *** | J11: =_xlfn.IFNA(VLOOKUP(A12,Argentina!A:I,9,FALSE)," ") | K11: =_xlfn.IFNA(VLOOKUP($A12,Bolivia!$A:$I,9,FALSE)," ") -> ** | L11: =_xlfn.IFNA(VLOOKUP($A12,Brazil!$A:$I,9,FALSE)," ") | M11: =_xlfn.IFNA(VLOOKUP($A12,Chile!$A:$I,9,FALSE)," ") | N11: =_xlfn.IFNA(VLOOKUP($A12,Colombia!$A:$I,9,FALSE)," ") -> * | O11: =_xlfn.IFNA(VLOOKUP($A12,Ecuador!$A:$I,9,FALSE)," ") -> ** | P11: =_xlfn.IFNA(VLOOKUP($A12,Guatemala!$A:$I,9,FALSE)," ") | Q11: =_xlfn.IFNA(VLOOKUP($A12,Mexico!$A:$I,9,FALSE)," ") | R11: =_xlfn.IFNA(VLOOKUP($A12,Nicaragua!$A:$I,9,FALSE)," ") | S11: =_xlfn.IFNA(VLOOKUP($A12,Peru!$A:$I,9,FALSE)," ") | T11: =_xlfn.IFNA(VLOOKUP($A12,PuertoRico!$A:$I,9,FALSE)," ") | U11: =_xlfn.IFNA(VLOOKUP($A12,Uruguay!$A:$I,9,FALSE)," ") | V11: =_xlfn.IFNA(VLOOKUP($A12,Venezuela!$A:$I,9,FALSE)," ") -> ***
A12: (B) Membership: charitable/humanitarian organization | B12: 0.189 | C12: 0.392 | D12: 0.18 | E12: 0.384 | F12: 0.184 | G12: 0.388 | H12: 0.325 | I12: =IF(H12>0.1,"", IF(AND(H12<=0.1,H12>0.05),"*", IF(AND(H12<=0.05,H12>0.01),"**", IF(H12<=0.01,"***","")))) | J12: =_xlfn.IFNA(VLOOKUP(A13,Argentina!A:I,9,FALSE)," ") | K12: =_xlfn.IFNA(VLOOKUP($A13,Bolivia!$A:$I,9,FALSE)," ") -> ** | L12: =_xlfn.IFNA(VLOOKUP($A13,Brazil!$A:$I,9,FALSE)," ") -> ** | M12: =_xlfn.IFNA(VLOOKUP($A13,Chile!$A:$I,9,FALSE)," ") | N12: =_xlfn.IFNA(VLOOKUP($A13,Colombia!$A:$I,9,FALSE)," ") -> ** | O12: =_xlfn.IFNA(VLOOKUP($A13,Ecuador!$A:$I,9,FALSE)," ") | P12: =_xlfn.IFNA(VLOOKUP($A13,Guatemala!$A:$I,9,FALSE)," ") | Q12: =_xlfn.IFNA(VLOOKUP($A13,Mexico!$A:$I,9,FALSE)," ") | R12: =_xlfn.IFNA(VLOOKUP($A13,Nicaragua!$A:$I,9,FALSE)," ") | S12: =_xlfn.IFNA(VLOOKUP($A13,Peru!$A:$I,9,FALSE)," ") -> *** | T12: =_xlfn.IFNA(VLOOKUP($A13,PuertoRico!$A:$I,9,FALSE)," ") | U12: =_xlfn.IFNA(VLOOKUP($A13,Uruguay!$A:$I,9,FALSE)," ") | V12: =_xlfn.IFNA(VLOOKUP($A13,Venezuela!$A:$I,9,FALSE)," ")
A13: (B) Political actions online: Encouraging others to act | B13: 0.906 | C13: 0.292 | D13: 0.93 | E13: 0.254 | F13: 0.919 | G13: 0.274 | H13: <0,001 | I13: =IF(H13>0.1,"", IF(AND(H13<=0.1,H13>0.05),"*", IF(AND(H13<=0.05,H13>0.01),"**", IF(H13<=0.01,"***","")))) | J13: =_xlfn.IFNA(VLOOKUP(A14,Argentina!A:I,9,FALSE)," ") | K13: =_xlfn.IFNA(VLOOKUP($A14,Bolivia!$A:$I,9,FALSE)," ") -> ** | L13: =_xlfn.IFNA(VLOOKUP($A14,Brazil!$A:$I,9,FALSE)," ") -> * | M13: =_xlfn.IFNA(VLOOKUP($A14,Chile!$A:$I,9,FALSE)," ") | N13: =_xlfn.IFNA(VLOOKUP($A14,Colombia!$A:$I,9,FALSE)," ") | O13: =_xlfn.IFNA(VLOOKUP($A14,Ecuador!$A:$I,9,FALSE)," ") | P13: =_xlfn.IFNA(VLOOKUP($A14,Guatemala!$A:$I,9,FALSE)," ") -> *** | Q13: =_xlfn.IFNA(VLOOKUP($A14,Mexico!$A:$I,9,FALSE)," ") | R13: =_xlfn.IFNA(VLOOKUP($A14,Nicaragua!$A:$I,9,FALSE)," ") | S13: =_xlfn.IFNA(VLOOKUP($A14,Peru!$A:$I,9,FALSE)," ") | T13: =_xlfn.IFNA(VLOOKUP($A14,PuertoRico!$A:$I,9,FALSE)," ") | U13: =_xlfn.IFNA(VLOOKUP($A14,Uruguay!$A:$I,9,FALSE)," ") | V13: =_xlfn.IFNA(VLOOKUP($A14,Venezuela!$A:$I,9,FALSE)," ")
A14: (B) Political actions online: Searching information | B14: 0.754 | C14: 0.431 | D14: 0.778 | E14: 0.416 | F14: 0.766 | G14: 0.423 | H14: 0.02 | I14: =IF(H14>0.1,"", IF(AND(H14<=0.1,H14>0.05),"*", IF(AND(H14<=0.05,H14>0.01),"**", IF(H14<=0.01,"***","")))) -> ** | J14: =_xlfn.IFNA(VLOOKUP(A15,Argentina!A:I,9,FALSE)," ") | K14: =_xlfn.IFNA(VLOOKUP($A15,Bolivia!$A:$I,9,FALSE)," ") | L14: =_xlfn.IFNA(VLOOKUP($A15,Brazil!$A:$I,9,FALSE)," ") | M14: =_xlfn.IFNA(VLOOKUP($A15,Chile!$A:$I,9,FALSE)," ") | N14: =_xlfn.IFNA(VLOOKUP($A15,Colombia!$A:$I,9,FALSE)," ") | O14: =_xlfn.IFNA(VLOOKUP($A15,Ecuador!$A:$I,9,FALSE)," ") -> ** | P14: =_xlfn.IFNA(VLOOKUP($A15,Guatemala!$A:$I,9,FALSE)," ") | Q14: =_xlfn.IFNA(VLOOKUP($A15,Mexico!$A:$I,9,FALSE)," ") | R14: =_xlfn.IFNA(VLOOKUP($A15,Nicaragua!$A:$I,9,FALSE)," ") | S14: =_xlfn.IFNA(VLOOKUP($A15,Peru!$A:$I,9,FALSE)," ") | T14: =_xlfn.IFNA(VLOOKUP($A15,PuertoRico!$A:$I,9,FALSE)," ") | U14: =_xlfn.IFNA(VLOOKUP($A15,Uruguay!$A:$I,9,FALSE)," ") | V14: =_xlfn.IFNA(VLOOKUP($A15,Venezuela!$A:$I,9,FALSE)," ")
A15: (B) Political actions online: Organizing activities/protests | B15: 0.948 | C15: 0.222 | D15: 0.954 | E15: 0.209 | F15: 0.951 | G15: 0.216 | H15: 0.231 | I15: =IF(H15>0.1,"", IF(AND(H15<=0.1,H15>0.05),"*", IF(AND(H15<=0.05,H15>0.01),"**", IF(H15<=0.01,"***","")))) | J15: =_xlfn.IFNA(VLOOKUP(A16,Argentina!A:I,9,FALSE)," ") | K15: =_xlfn.IFNA(VLOOKUP($A16,Bolivia!$A:$I,9,FALSE)," ") -> *** | L15: =_xlfn.IFNA(VLOOKUP($A16,Brazil!$A:$I,9,FALSE)," ") | M15: =_xlfn.IFNA(VLOOKUP($A16,Chile!$A:$I,9,FALSE)," ") | N15: =_xlfn.IFNA(VLOOKUP($A16,Colombia!$A:$I,9,FALSE)," ") -> * | O15: =_xlfn.IFNA(VLOOKUP($A16,Ecuador!$A:$I,9,FALSE)," ") | P15: =_xlfn.IFNA(VLOOKUP($A16,Guatemala!$A:$I,9,FALSE)," ") | Q15: =_xlfn.IFNA(VLOOKUP($A16,Mexico!$A:$I,9,FALSE)," ") | R15: =_xlfn.IFNA(VLOOKUP($A16,Nicaragua!$A:$I,9,FALSE)," ") | S15: =_xlfn.IFNA(VLOOKUP($A16,Peru!$A:$I,9,FALSE)," ") -> *** | T15: =_xlfn.IFNA(VLOOKUP($A16,PuertoRico!$A:$I,9,FALSE)," ") | U15: =_xlfn.IFNA(VLOOKUP($A16,Uruguay!$A:$I,9,FALSE)," ") | V15: =_xlfn.IFNA(VLOOKUP($A16,Venezuela!$A:$I,9,FALSE)," ")
A16: (B) Information source: Daily newspaper | B16: 0.831 | C16: 0.375 | D16: 0.853 | E16: 0.354 | F16: 0.842 | G16: 0.364 | H16: 0.011 | I16: =IF(H16>0.1,"", IF(AND(H16<=0.1,H16>0.05),"*", IF(AND(H16<=0.05,H16>0.01),"**", IF(H16<=0.01,"***","")))) -> ** | J16: =_xlfn.IFNA(VLOOKUP(A17,Argentina!A:I,9,FALSE)," ") | K16: =_xlfn.IFNA(VLOOKUP($A17,Bolivia!$A:$I,9,FALSE)," ") -> * | L16: =_xlfn.IFNA(VLOOKUP($A17,Brazil!$A:$I,9,FALSE)," ") | M16: =_xlfn.IFNA(VLOOKUP($A17,Chile!$A:$I,9,FALSE)," ") | N16: =_xlfn.IFNA(VLOOKUP($A17,Colombia!$A:$I,9,FALSE)," ") | O16: =_xlfn.IFNA(VLOOKUP($A17,Ecuador!$A:$I,9,FALSE)," ") -> *** | P16: =_xlfn.IFNA(VLOOKUP($A17,Guatemala!$A:$I,9,FALSE)," ") | Q16: =_xlfn.IFNA(VLOOKUP($A17,Mexico!$A:$I,9,FALSE)," ") -> * | R16: =_xlfn.IFNA(VLOOKUP($A17,Nicaragua!$A:$I,9,FALSE)," ") | S16: =_xlfn.IFNA(VLOOKUP($A17,Peru!$A:$I,9,FALSE)," ") | T16: =_xlfn.IFNA(VLOOKUP($A17,PuertoRico!$A:$I,9,FALSE)," ") | U16: =_xlfn.IFNA(VLOOKUP($A17,Uruguay!$A:$I,9,FALSE)," ") | V16: =_xlfn.IFNA(VLOOKUP($A17,Venezuela!$A:$I,9,FALSE)," ") -> **
A17: (B) Information source: TV news | B17: 0.446 | C17: 0.497 | D17: 0.407 | E17: 0.491 | F17: 0.426 | G17: 0.494 | H17: <0,001 | I17: =IF(H17>0.1,"", IF(AND(H17<=0.1,H17>0.05),"*", IF(AND(H17<=0.05,H17>0.01),"**", IF(H17<=0.01,"***","")))) | J17: =_xlfn.IFNA(VLOOKUP(A18,Argentina!A:I,9,FALSE)," ") | K17: =_xlfn.IFNA(VLOOKUP($A18,Bolivia!$A:$I,9,FALSE)," ") | L17: =_xlfn.IFNA(VLOOKUP($A18,Brazil!$A:$I,9,FALSE)," ") | M17: =_xlfn.IFNA(VLOOKUP($A18,Chile!$A:$I,9,FALSE)," ") | N17: =_xlfn.IFNA(VLOOKUP($A18,Colombia!$A:$I,9,FALSE)," ") | O17: =_xlfn.IFNA(VLOOKUP($A18,Ecuador!$A:$I,9,FALSE)," ") -> * | P17: =_xlfn.IFNA(VLOOKUP($A18,Guatemala!$A:$I,9,FALSE)," ") | Q17: =_xlfn.IFNA(VLOOKUP($A18,Mexico!$A:$I,9,FALSE)," ") | R17: =_xlfn.IFNA(VLOOKUP($A18,Nicaragua!$A:$I,9,FALSE)," ") | S17: =_xlfn.IFNA(VLOOKUP($A18,Peru!$A:$I,9,FALSE)," ") | T17: =_xlfn.IFNA(VLOOKUP($A18,PuertoRico!$A:$I,9,FALSE)," ") | U17: =_xlfn.IFNA(VLOOKUP($A18,Uruguay!$A:$I,9,FALSE)," ") | V17: =_xlfn.IFNA(VLOOKUP($A18,Venezuela!$A:$I,9,FALSE)," ")
A18: (B) Information source: Radio news | B18: 0.728 | C18: 0.445 | D18: 0.731 | E18: 0.443 | F18: 0.73 | G18: 0.444 | H18: 0.796 | I18: =IF(H18>0.1,"", IF(AND(H18<=0.1,H18>0.05),"*", IF(AND(H18<=0.05,H18>0.01),"**", IF(H18<=0.01,"***","")))) | J18: =_xlfn.IFNA(VLOOKUP(A19,Argentina!A:I,9,FALSE)," ") | K18: =_xlfn.IFNA(VLOOKUP($A19,Bolivia!$A:$I,9,FALSE)," ") -> *** | L18: =_xlfn.IFNA(VLOOKUP($A19,Brazil!$A:$I,9,FALSE)," ") | M18: =_xlfn.IFNA(VLOOKUP($A19,Chile!$A:$I,9,FALSE)," ") | N18: =_xlfn.IFNA(VLOOKUP($A19,Colombia!$A:$I,9,FALSE)," ") -> ** | O18: =_xlfn.IFNA(VLOOKUP($A19,Ecuador!$A:$I,9,FALSE)," ") | P18: =_xlfn.IFNA(VLOOKUP($A19,Guatemala!$A:$I,9,FALSE)," ") | Q18: =_xlfn.IFNA(VLOOKUP($A19,Mexico!$A:$I,9,FALSE)," ") | R18: =_xlfn.IFNA(VLOOKUP($A19,Nicaragua!$A:$I,9,FALSE)," ") -> ** | S18: =_xlfn.IFNA(VLOOKUP($A19,Peru!$A:$I,9,FALSE)," ") | T18: =_xlfn.IFNA(VLOOKUP($A19,PuertoRico!$A:$I,9,FALSE)," ") | U18: =_xlfn.IFNA(VLOOKUP($A19,Uruguay!$A:$I,9,FALSE)," ") | V18: =_xlfn.IFNA(VLOOKUP($A19,Venezuela!$A:$I,9,FALSE)," ")
A19: (B) Information source: Internet | B19: 0.389 | C19: 0.488 | D19: 0.419 | E19: 0.493 | F19: 0.404 | G19: 0.491 | H19: 0.009 | I19: =IF(H19>0.1,"", IF(AND(H19<=0.1,H19>0.05),"*", IF(AND(H19<=0.05,H19>0.01),"**", IF(H19<=0.01,"***","")))) -> *** | J19: =_xlfn.IFNA(VLOOKUP(A20,Argentina!A:I,9,FALSE)," ") | K19: =_xlfn.IFNA(VLOOKUP($A20,Bolivia!$A:$I,9,FALSE)," ") -> *** | L19: =_xlfn.IFNA(VLOOKUP($A20,Brazil!$A:$I,9,FALSE)," ") | M19: =_xlfn.IFNA(VLOOKUP($A20,Chile!$A:$I,9,FALSE)," ") | N19: =_xlfn.IFNA(VLOOKUP($A20,Colombia!$A:$I,9,FALSE)," ") | O19: =_xlfn.IFNA(VLOOKUP($A20,Ecuador!$A:$I,9,FALSE)," ") | P19: =_xlfn.IFNA(VLOOKUP($A20,Guatemala!$A:$I,9,FALSE)," ") | Q19: =_xlfn.IFNA(VLOOKUP($A20,Mexico!$A:$I,9,FALSE)," ") | R19: =_xlfn.IFNA(VLOOKUP($A20,Nicaragua!$A:$I,9,FALSE)," ") | S19: =_xlfn.IFNA(VLOOKUP($A20,Peru!$A:$I,9,FALSE)," ") | T19: =_xlfn.IFNA(VLOOKUP($A20,PuertoRico!$A:$I,9,FALSE)," ") | U19: =_xlfn.IFNA(VLOOKUP($A20,Uruguay!$A:$I,9,FALSE)," ") | V19: =_xlfn.IFNA(VLOOKUP($A20,Venezuela!$A:$I,9,FALSE)," ") -> *
A20: (B) Information source: Social media | B20: 0.372 | C20: 0.484 | D20: 0.39 | E20: 0.488 | F20: 0.382 | G20: 0.486 | H20: 0.117 | I20: =IF(H20>0.1,"", IF(AND(H20<=0.1,H20>0.05),"*", IF(AND(H20<=0.05,H20>0.01),"**", IF(H20<=0.01,"***","")))) | J20: =_xlfn.IFNA(VLOOKUP(A21,Argentina!A:I,9,FALSE)," ") -> ** | K20: =_xlfn.IFNA(VLOOKUP($A21,Bolivia!$A:$I,9,FALSE)," ") -> *** | L20: =_xlfn.IFNA(VLOOKUP($A21,Brazil!$A:$I,9,FALSE)," ") -> ** | M20: =_xlfn.IFNA(VLOOKUP($A21,Chile!$A:$I,9,FALSE)," ") | N20: =_xlfn.IFNA(VLOOKUP($A21,Colombia!$A:$I,9,FALSE)," ") -> *** | O20: =_xlfn.IFNA(VLOOKUP($A21,Ecuador!$A:$I,9,FALSE)," ") -> ** | P20: =_xlfn.IFNA(VLOOKUP($A21,Guatemala!$A:$I,9,FALSE)," ") | Q20: =_xlfn.IFNA(VLOOKUP($A21,Mexico!$A:$I,9,FALSE)," ") | R20: =_xlfn.IFNA(VLOOKUP($A21,Nicaragua!$A:$I,9,FALSE)," ") | S20: =_xlfn.IFNA(VLOOKUP($A21,Peru!$A:$I,9,FALSE)," ") -> ** | T20: =_xlfn.IFNA(VLOOKUP($A21,PuertoRico!$A:$I,9,FALSE)," ") | U20: =_xlfn.IFNA(VLOOKUP($A21,Uruguay!$A:$I,9,FALSE)," ") | V20: =_xlfn.IFNA(VLOOKUP($A21,Venezuela!$A:$I,9,FALSE)," ")
A21: (B) Interest in politics (high vs low) | B21: 0.374 | C21: 0.484 | D21: 0.307 | E21: 0.461 | F21: 0.339 | G21: 0.473 | H21: <0,001 | I21: =IF(H21>0.1,"", IF(AND(H21<=0.1,H21>0.05),"*", IF(AND(H21<=0.05,H21>0.01),"**", IF(H21<=0.01,"***","")))) | J21: =_xlfn.IFNA(VLOOKUP(A22,Argentina!A:I,9,FALSE)," ") | N21: =_xlfn.IFNA(VLOOKUP($A22,Colombia!$A:$I,9,FALSE)," ") -> ** | O21: =_xlfn.IFNA(VLOOKUP($A22,Ecuador!$A:$I,9,FALSE)," ") | P21: =_xlfn.IFNA(VLOOKUP($A22,Guatemala!$A:$I,9,FALSE)," ") | Q21: =_xlfn.IFNA(VLOOKUP($A22,Mexico!$A:$I,9,FALSE)," ") | R21: =_xlfn.IFNA(VLOOKUP($A22,Nicaragua!$A:$I,9,FALSE)," ") | S21: =_xlfn.IFNA(VLOOKUP($A22,Peru!$A:$I,9,FALSE)," ") | U21: =_xlfn.IFNA(VLOOKUP($A22,Uruguay!$A:$I,9,FALSE)," ") | V21: =_xlfn.IFNA(VLOOKUP($A22,Venezuela!$A:$I,9,FALSE)," ")
A22: (B) How much system allows people to have a say | B22: 0.395 | C22: 0.489 | D22: 0.348 | E22: 0.476 | F22: 0.371 | G22: 0.483 | H22: 0.002 | I22: =IF(H22>0.1,"", IF(AND(H22<=0.1,H22>0.05),"*", IF(AND(H22<=0.05,H22>0.01),"**", IF(H22<=0.01,"***","")))) -> *** | J22: =_xlfn.IFNA(VLOOKUP(A23,Argentina!A:I,9,FALSE)," ") | K22: =_xlfn.IFNA(VLOOKUP($A23,Bolivia!$A:$I,9,FALSE)," ") | L22: =_xlfn.IFNA(VLOOKUP($A23,Brazil!$A:$I,9,FALSE)," ") | M22: =_xlfn.IFNA(VLOOKUP($A23,Chile!$A:$I,9,FALSE)," ") | N22: =_xlfn.IFNA(VLOOKUP($A23,Colombia!$A:$I,9,FALSE)," ") | O22: =_xlfn.IFNA(VLOOKUP($A23,Ecuador!$A:$I,9,FALSE)," ") | P22: =_xlfn.IFNA(VLOOKUP($A23,Guatemala!$A:$I,9,FALSE)," ") | Q22: =_xlfn.IFNA(VLOOKUP($A23,Mexico!$A:$I,9,FALSE)," ") | R22: =_xlfn.IFNA(VLOOKUP($A23,Nicaragua!$A:$I,9,FALSE)," ") | S22: =_xlfn.IFNA(VLOOKUP($A23,Peru!$A:$I,9,FALSE)," ") | T22: =_xlfn.IFNA(VLOOKUP($A23,PuertoRico!$A:$I,9,FALSE)," ") | U22: =_xlfn.IFNA(VLOOKUP($A23,Uruguay!$A:$I,9,FALSE)," ") | V22: =_xlfn.IFNA(VLOOKUP($A23,Venezuela!$A:$I,9,FALSE)," ")
A23: (B) Satisfaction with political system performance | B23: 0.344 | C23: 0.475 | D23: 0.35 | E23: 0.477 | F23: 0.347 | G23: 0.476 | H23: 0.607 | I23: =IF(H23>0.1,"", IF(AND(H23<=0.1,H23>0.05),"*", IF(AND(H23<=0.05,H23>0.01),"**", IF(H23<=0.01,"***","")))) | J23: =_xlfn.IFNA(VLOOKUP(A24,Argentina!A:I,9,FALSE)," ") | K23: =_xlfn.IFNA(VLOOKUP($A24,Bolivia!$A:$I,9,FALSE)," ") | L23: =_xlfn.IFNA(VLOOKUP($A24,Brazil!$A:$I,9,FALSE)," ") | M23: =_xlfn.IFNA(VLOOKUP($A24,Chile!$A:$I,9,FALSE)," ") | N23: =_xlfn.IFNA(VLOOKUP($A24,Colombia!$A:$I,9,FALSE)," ") | O23: =_xlfn.IFNA(VLOOKUP($A24,Ecuador!$A:$I,9,FALSE)," ") | P23: =_xlfn.IFNA(VLOOKUP($A24,Guatemala!$A:$I,9,FALSE)," ") | Q23: =_xlfn.IFNA(VLOOKUP($A24,Mexico!$A:$I,9,FALSE)," ") | R23: =_xlfn.IFNA(VLOOKUP($A24,Nicaragua!$A:$I,9,FALSE)," ") | S23: =_xlfn.IFNA(VLOOKUP($A24,Peru!$A:$I,9,FALSE)," ") | T23: =_xlfn.IFNA(VLOOKUP($A24,PuertoRico!$A:$I,9,FALSE)," ") | U23: =_xlfn.IFNA(VLOOKUP($A24,Uruguay!$A:$I,9,FALSE)," ") | V23: =_xlfn.IFNA(VLOOKUP($A24,Venezuela!$A:$I,9,FALSE)," ")
A24: (B) Having a democratic political system | B24: 0.84 | C24: 0.366 | D24: 0.847 | E24: 0.36 | F24: 0.844 | G24: 0.363 | H24: 0.472 | I24: =IF(H24>0.1,"", IF(AND(H24<=0.1,H24>0.05),"*", IF(AND(H24<=0.05,H24>0.01),"**", IF(H24<=0.01,"***","")))) | J24: =_xlfn.IFNA(VLOOKUP(A25,Argentina!A:I,9,FALSE)," ") | K24: =_xlfn.IFNA(VLOOKUP($A25,Bolivia!$A:$I,9,FALSE)," ") | L24: =_xlfn.IFNA(VLOOKUP($A25,Brazil!$A:$I,9,FALSE)," ") -> ** | M24: =_xlfn.IFNA(VLOOKUP($A25,Chile!$A:$I,9,FALSE)," ") | N24: =_xlfn.IFNA(VLOOKUP($A25,Colombia!$A:$I,9,FALSE)," ") | O24: =_xlfn.IFNA(VLOOKUP($A25,Ecuador!$A:$I,9,FALSE)," ") -> *** | P24: =_xlfn.IFNA(VLOOKUP($A25,Guatemala!$A:$I,9,FALSE)," ") | Q24: =_xlfn.IFNA(VLOOKUP($A25,Mexico!$A:$I,9,FALSE)," ") | R24: =_xlfn.IFNA(VLOOKUP($A25,Nicaragua!$A:$I,9,FALSE)," ") | S24: =_xlfn.IFNA(VLOOKUP($A25,Peru!$A:$I,9,FALSE)," ") | T24: =_xlfn.IFNA(VLOOKUP($A25,PuertoRico!$A:$I,9,FALSE)," ") | U24: =_xlfn.IFNA(VLOOKUP($A25,Uruguay!$A:$I,9,FALSE)," ") | V24: =_xlfn.IFNA(VLOOKUP($A25,Venezuela!$A:$I,9,FALSE)," ")
A25: (B) Importance of democracy | B25: 0.843 | C25: 0.364 | D25: 0.846 | E25: 0.361 | F25: 0.845 | G25: 0.362 | H25: 0.674 | I25: =IF(H25>0.1,"", IF(AND(H25<=0.1,H25>0.05),"*", IF(AND(H25<=0.05,H25>0.01),"**", IF(H25<=0.01,"***","")))) | J25: =_xlfn.IFNA(VLOOKUP(A26,Argentina!A:I,9,FALSE)," ") | K25: =_xlfn.IFNA(VLOOKUP($A26,Bolivia!$A:$I,9,FALSE)," ") | L25: =_xlfn.IFNA(VLOOKUP($A26,Brazil!$A:$I,9,FALSE)," ") | M25: =_xlfn.IFNA(VLOOKUP($A26,Chile!$A:$I,9,FALSE)," ") | N25: =_xlfn.IFNA(VLOOKUP($A26,Colombia!$A:$I,9,FALSE)," ") | O25: =_xlfn.IFNA(VLOOKUP($A26,Ecuador!$A:$I,9,FALSE)," ") | P25: =_xlfn.IFNA(VLOOKUP($A26,Guatemala!$A:$I,9,FALSE)," ") | Q25: =_xlfn.IFNA(VLOOKUP($A26,Mexico!$A:$I,9,FALSE)," ") | R25: =_xlfn.IFNA(VLOOKUP($A26,Nicaragua!$A:$I,9,FALSE)," ") -> * | S25: =_xlfn.IFNA(VLOOKUP($A26,Peru!$A:$I,9,FALSE)," ") | T25: =_xlfn.IFNA(VLOOKUP($A26,PuertoRico!$A:$I,9,FALSE)," ") | U25: =_xlfn.IFNA(VLOOKUP($A26,Uruguay!$A:$I,9,FALSE)," ") | V25: =_xlfn.IFNA(VLOOKUP($A26,Venezuela!$A:$I,9,FALSE)," ")
A26: (B) Confidence: The Government | B26: 0.197 | C26: 0.397 | D26: 0.189 | E26: 0.392 | F26: 0.193 | G26: 0.394 | H26: 0.414 | I26: =IF(H26>0.1,"", IF(AND(H26<=0.1,H26>0.05),"*", IF(AND(H26<=0.05,H26>0.01),"**", IF(H26<=0.01,"***","")))) | J26: =_xlfn.IFNA(VLOOKUP(A27,Argentina!A:I,9,FALSE)," ") | K26: =_xlfn.IFNA(VLOOKUP($A27,Bolivia!$A:$I,9,FALSE)," ") | L26: =_xlfn.IFNA(VLOOKUP($A27,Brazil!$A:$I,9,FALSE)," ") | M26: =_xlfn.IFNA(VLOOKUP($A27,Chile!$A:$I,9,FALSE)," ") | N26: =_xlfn.IFNA(VLOOKUP($A27,Colombia!$A:$I,9,FALSE)," ") | O26: =_xlfn.IFNA(VLOOKUP($A27,Ecuador!$A:$I,9,FALSE)," ") | P26: =_xlfn.IFNA(VLOOKUP($A27,Guatemala!$A:$I,9,FALSE)," ") | Q26: =_xlfn.IFNA(VLOOKUP($A27,Mexico!$A:$I,9,FALSE)," ") | R26: =_xlfn.IFNA(VLOOKUP($A27,Nicaragua!$A:$I,9,FALSE)," ") | S26: =_xlfn.IFNA(VLOOKUP($A27,Peru!$A:$I,9,FALSE)," ") | T26: =_xlfn.IFNA(VLOOKUP($A27,PuertoRico!$A:$I,9,FALSE)," ") | U26: =_xlfn.IFNA(VLOOKUP($A27,Uruguay!$A:$I,9,FALSE)," ") | V26: =_xlfn.IFNA(VLOOKUP($A27,Venezuela!$A:$I,9,FALSE)," ")
A27: (B) Confidence: The Political Parties | B27: 0.103 | C27: 0.303 | D27: 0.101 | E27: 0.302 | F27: 0.102 | G27: 0.303 | H27: 0.878 | I27: =IF(H27>0.1,"", IF(AND(H27<=0.1,H27>0.05),"*", IF(AND(H27<=0.05,H27>0.01),"**", IF(H27<=0.01,"***","")))) | J27: =_xlfn.IFNA(VLOOKUP(A28,Argentina!A:I,9,FALSE)," ") | K27: =_xlfn.IFNA(VLOOKUP($A28,Bolivia!$A:$I,9,FALSE)," ") | L27: =_xlfn.IFNA(VLOOKUP($A28,Brazil!$A:$I,9,FALSE)," ") | M27: =_xlfn.IFNA(VLOOKUP($A28,Chile!$A:$I,9,FALSE)," ") | N27: =_xlfn.IFNA(VLOOKUP($A28,Colombia!$A:$I,9,FALSE)," ") | O27: =_xlfn.IFNA(VLOOKUP($A28,Ecuador!$A:$I,9,FALSE)," ") | P27: =_xlfn.IFNA(VLOOKUP($A28,Guatemala!$A:$I,9,FALSE)," ") | Q27: =_xlfn.IFNA(VLOOKUP($A28,Mexico!$A:$I,9,FALSE)," ") | R27: =_xlfn.IFNA(VLOOKUP($A28,Nicaragua!$A:$I,9,FALSE)," ") | S27: =_xlfn.IFNA(VLOOKUP($A28,Peru!$A:$I,9,FALSE)," ") | T27: =_xlfn.IFNA(VLOOKUP($A28,PuertoRico!$A:$I,9,FALSE)," ") | U27: =_xlfn.IFNA(VLOOKUP($A28,Uruguay!$A:$I,9,FALSE)," ") | V27: =_xlfn.IFNA(VLOOKUP($A28,Venezuela!$A:$I,9,FALSE)," ")
A28: (B) Confidence: Parliament | B28: 0.145 | C28: 0.352 | D28: 0.135 | E28: 0.342 | F28: 0.14 | G28: 0.347 | H28: 0.213 | I28: =IF(H28>0.1,"", IF(AND(H28<=0.1,H28>0.05),"*", IF(AND(H28<=0.05,H28>0.01),"**", IF(H28<=0.01,"***","")))) | J28: =_xlfn.IFNA(VLOOKUP(A29,Argentina!A:I,9,FALSE)," ") | K28: =_xlfn.IFNA(VLOOKUP($A29,Bolivia!$A:$I,9,FALSE)," ") | L28: =_xlfn.IFNA(VLOOKUP($A29,Brazil!$A:$I,9,FALSE)," ") | M28: =_xlfn.IFNA(VLOOKUP($A29,Chile!$A:$I,9,FALSE)," ") | N28: =_xlfn.IFNA(VLOOKUP($A29,Colombia!$A:$I,9,FALSE)," ") | O28: =_xlfn.IFNA(VLOOKUP($A29,Ecuador!$A:$I,9,FALSE)," ") | P28: =_xlfn.IFNA(VLOOKUP($A29,Guatemala!$A:$I,9,FALSE)," ") | Q28: =_xlfn.IFNA(VLOOKUP($A29,Mexico!$A:$I,9,FALSE)," ") | R28: =_xlfn.IFNA(VLOOKUP($A29,Nicaragua!$A:$I,9,FALSE)," ") | S28: =_xlfn.IFNA(VLOOKUP($A29,Peru!$A:$I,9,FALSE)," ") | T28: =_xlfn.IFNA(VLOOKUP($A29,PuertoRico!$A:$I,9,FALSE)," ") | U28: =_xlfn.IFNA(VLOOKUP($A29,Uruguay!$A:$I,9,FALSE)," ") | V28: =_xlfn.IFNA(VLOOKUP($A29,Venezuela!$A:$I,9,FALSE)," ")
J29: =24-COUNTBLANK(J4:J28) -> 1 | K29: =24-COUNTBLANK(K4:K28) -> 11 | L29: =24-COUNTBLANK(L4:L28) -> 6 | M29: =24-COUNTBLANK(M4:M28) -> 1 | N29: =24-COUNTBLANK(N4:N28) -> 9 | O29: =24-COUNTBLANK(O4:O28) -> 9 | P29: =24-COUNTBLANK(P4:P28) -> 4 | Q29: =24-COUNTBLANK(Q4:Q28) -> 3 | ... V29: =24-COUNTBLANK(V4:V28) -> 3

Sheet Argentina
A1: Country: Argentina
B2: Male | D2: Female | F2: Total
B3: % | C3: Sd | D3: % | E3: Sd | F3: % | G3: Sd | H3: Test | I3: p-value
A4: N | B4: 194 | C4: 0.48622 | D4: 205 | E4: 0.51378 | F4: 399 | G4: 1
A5: (B) Political action: attending lawful/peaceful demonstrations | B5: 0.822 | C5: 0.383 | D5: 0.856 | E5: 0.352 | F5: 0.84 | G5: 0.367 | H5: 0.38 | I5: =IF(H5>0.1,"", IF(AND(H5<=0.1,H5>0.05),"*", IF(AND(H5<=0.05,H5>0.01),"**", IF(H5<=0.01,"***",""))))
A6: (B) Political action: Signing a petition | B6: 0.806 | C6: 0.396 | D6: 0.774 | E6: 0.419 | F6: 0.79 | G6: 0.408 | H6: 0.443 | I6: =IF(H6>0.1,"", IF(AND(H6<=0.1,H6>0.05),"*", IF(AND(H6<=0.05,H6>0.01),"**", IF(H6<=0.01,"***",""))))
A7: (B) Political action: joining in boycotts | B7: 0.961 | C7: 0.195 | D7: 0.978 | E7: 0.147 | F7: 0.969 | G7: 0.173 | H7: 0.345 | I7: =IF(H7>0.1,"", IF(AND(H7<=0.1,H7>0.05),"*", IF(AND(H7<=0.05,H7>0.01),"**", IF(H7<=0.01,"***",""))))
A8: (B) Active/Inactive membership: Political party | B8: 0.103 | C8: 0.305 | D8: 0.063 | E8: 0.244 | F8: 0.083 | G8: 0.276 | H8: 0.151 | I8: =IF(H8>0.1,"", IF(AND(H8<=0.1,H8>0.05),"*", IF(AND(H8<=0.05,H8>0.01),"**", IF(H8<=0.01,"***",""))))
A9: (B) Social activism: Contacting a government official | B9: 0.78 | C9: 0.416 | D9: 0.713 | E9: 0.454 | F9: 0.745 | G9: 0.436 | H9: 0.136 | I9: =IF(H9>0.1,"", IF(AND(H9<=0.1,H9>0.05),"*", IF(AND(H9<=0.05,H9>0.01),"**", IF(H9<=0.01,"***",""))))
A10: (B) Social activism: Donating to a group or campaign | B10: 0.469 | C10: 0.5 | D10: 0.512 | E10: 0.501 | F10: 0.491 | G10: 0.501 | H10: 0.39 | I10: =IF(H10>0.1,"", IF(AND(H10<=0.1,H10>0.05),"*", IF(AND(H10<=0.05,H10>0.01),"**", IF(H10<=0.01,"***",""))))
A11: (B) Social activism: Encouraging others to take action | B11: 0.931 | C11: 0.255 | D11: 0.923 | E11: 0.268 | F11: 0.927 | G11: 0.261 | H11: 0.774 | I11: =IF(H11>0.1,"", IF(AND(H11<=0.1,H11>0.05),"*", IF(AND(H11<=0.05,H11>0.01),"**", IF(H11<=0.01,"***",""))))
A12: (B) Political action: joining unofficial strikes | B12: 0.819 | C12: 0.386 | D12: 0.876 | E12: 0.331 | F12: 0.848 | G12: 0.359 | H12: 0.135 | I12: =IF(H12>0.1,"", IF(AND(H12<=0.1,H12>0.05),"*", IF(AND(H12<=0.05,H12>0.01),"**", IF(H12<=0.01,"***",""))))
A13: (B) Membership: charitable/humanitarian organization | B13: 0.113 | C13: 0.318 | D13: 0.098 | E13: 0.297 | F13: 0.105 | G13: 0.307 | H13: 0.607 | I13: =IF(H13>0.1,"", IF(AND(H13<=0.1,H13>0.05),"*", IF(AND(H13<=0.05,H13>0.01),"**", IF(H13<=0.01,"***",""))))
A14: (B) Political actions online: Encouraging others to act | B14: 0.909 | C14: 0.288 | D14: 0.908 | E14: 0.29 | F14: 0.909 | G14: 0.289 | H14: 0.974 | I14: =IF(H14>0.1,"", IF(AND(H14<=0.1,H14>0.05),"*", IF(AND(H14<=0.05,H14>0.01),"**", IF(H14<=0.01,"***",""))))
A15: (B) Political actions online: Searching information | B15: 0.793 | C15: 0.406 | D15: 0.799 | E15: 0.402 | F15: 0.796 | G15: 0.403 | H15: 0.892 | I15: =IF(H15>0.1,"", IF(AND(H15<=0.1,H15>0.05),"*", IF(AND(H15<=0.05,H15>0.01),"**", IF(H15<=0.01,"***",""))))
A16: (B) Political actions online: Organizing activities/protests | B16: 0.976 | C16: 0.152 | D16: 0.956 | E16: 0.207 | F16: 0.966 | G16: 0.182 | H16: 0.284 | I16: =IF(H16>0.1,"", IF(AND(H16<=0.1,H16>0.05),"*", IF(AND(H16<=0.05,H16>0.01),"**", IF(H16<=0.01,"***",""))))
... A29: (B) Confidence: Parliament | B29: 0.25 | C29: 0.434 | D29: 0.22 | E29: 0.415 | F29: 0.235 | G29: 0.424 | H29: 0.491 | I29: =IF(H29>0.1,"", IF(AND(H29<=0.1,H29>0.05),"*", IF(AND(H29<=0.05,H29>0.01),"**", IF(H29<=0.01,"***",""))))

Sheet Bolivia
A1: Country: Bolivia
B2: Male | D2: Female | F2: Total
B3: % | C3: Sd | D3: % | E3: Sd | F3: % | G3: Sd | H3: Test | I3: p-value
A4: N | B4: 493 | C4: 0.48051 | D4: 533 | E4: 0.51949 | F4: 1026 | G4: 1
A5: (B) Political action: attending lawful/peaceful demonstrations | B5: 0.863 | C5: 0.344 | D5: 0.873 | E5: 0.333 | F5: 0.868 | G5: 0.338 | H5: 0.636 | I5: =IF(H5>0.1,"", IF(AND(H5<=0.1,H5>0.05),"*", IF(AND(H5<=0.05,H5>0.01),"**", IF(H5<=0.01,"***",""))))
A6: (B) Political action: Signing a petition | B6: 0.895 | C6: 0.307 | D6: 0.912 | E6: 0.284 | F6: 0.903 | G6: 0.296 | H6: 0.361 | I6: =IF(H6>0.1,"", IF(AND(H6<=0.1,H6>0.05),"*", IF(AND(H6<=0.05,H6>0.01),"**", IF(H6<=0.01,"***",""))))
A7: (B) Political action: joining in boycotts | B7: 0.968 | C7: 0.177 | D7: 0.971 | E7: 0.168 | F7: 0.969 | G7: 0.172 | H7: 0.77 | I7: =IF(H7>0.1,"", IF(AND(H7<=0.1,H7>0.05),"*", IF(AND(H7<=0.05,H7>0.01),"**", IF(H7<=0.01,"***",""))))
A8: (B) Active/Inactive membership: Political party | B8: 0.106 | C8: 0.308 | D8: 0.055 | E8: 0.228 | F8: 0.079 | G8: 0.27 | H8: 0.003 | I8: =IF(H8>0.1,"", IF(AND(H8<=0.1,H8>0.05),"*", IF(AND(H8<=0.05,H8>0.01),"**", IF(H8<=0.01,"***","")))) -> ***
A9: (B) Social activism: Contacting a government official | B9: 0.778 | C9: 0.416 | D9: 0.788 | E9: 0.409 | F9: 0.783 | G9: 0.412 | H9: 0.701 | I9: =IF(H9>0.1,"", IF(AND(H9<=0.1,H9>0.05),"*", IF(AND(H9<=0.05,H9>0.01),"**", IF(H9<=0.01,"***",""))))
A10: (B) Social activism: Donating to a group or campaign | B10: 0.557 | C10: 0.497 | D10: 0.634 | E10: 0.482 | F10: 0.597 | G10: 0.491 | H10: 0.012 | I10: =IF(H10>0.1,"", IF(AND(H10<=0.1,H10>0.05),"*", IF(AND(H10<=0.05,H10>0.01),"**", IF(H10<=0.01,"***","")))) -> **
A11: (B) Social activism: Encouraging others to take action | B11: 0.933 | C11: 0.251 | D11: 0.957 | E11: 0.202 | F11: 0.945 | G11: 0.227 | H11: 0.082 | I11: =IF(H11>0.1,"", IF(AND(H11<=0.1,H11>0.05),"*", IF(AND(H11<=0.05,H11>0.01),"**", IF(H11<=0.01,"***","")))) -> *
A12: (B) Political action: joining unofficial strikes | B12: 0.916 | C12: 0.277 | D12: 0.908 | E12: 0.289 | F12: 0.912 | G12: 0.283 | H12: 0.656 | I12: =IF(H12>0.1,"", IF(AND(H12<=0.1,H12>0.05),"*", IF(AND(H12<=0.05,H12>0.01),"**", IF(H12<=0.01,"***",""))))
A13: (B) Membership: charitable/humanitarian organization | B13: 0.197 | C13: 0.398 | D13: 0.145 | E13: 0.353 | F13: 0.17 | G13: 0.376 | H13: 0.029 | I13: =IF(H13>0.1,"", IF(AND(H13<=0.1,H13>0.05),"*", IF(AND(H13<=0.05,H13>0.01),"**", IF(H13<=0.01,"***","")))) -> **
A14: (B) Political actions online: Encouraging others to act | B14: 0.95 | C14: 0.218 | D14: 0.98 | E14: 0.141 | F14: 0.965 | G14: 0.184 | H14: 0.012 | I14: =IF(H14>0.1,"", IF(AND(H14<=0.1,H14>0.05),"*", IF(AND(H14<=0.05,H14>0.01),"**", IF(H14<=0.01,"***","")))) -> **
A15: (B) Political actions online: Searching information | B15: 0.795 | C15: 0.404 | D15: 0.846 | E15: 0.362 | F15: 0.821 | G15: 0.384 | H15: 0.039 | I15: =IF(H15>0.1,"", IF(AND(H15<=0.1,H15>0.05),"*", IF(AND(H15<=0.05,H15>0.01),"**", IF(H15<=0.01,"***","")))) -> **
A16: (B) Political actions online: Organizing activities/protests | B16: 0.961 | C16: 0.194 | D16: 0.97 | E16: 0.17 | F16: 0.966 | G16: 0.183 | H16: 0.42 | I16: =IF(H16>0.1,"", IF(AND(H16<=0.1,H16>0.05),"*", IF(AND(H16<=0.05,H16>0.01),"**", IF(H16<=0.01,"***",""))))
A17: (B) Information source: Daily newspaper | B17: 0.864 | C17: 0.343 | D17: 0.936 | E17: 0.245 | F17: 0.901 | G17: 0.298 | H17: <0,001 | I17: ***
A18: (B) Information source: TV news | B18: 0.215 | C18: 0.411 | D18: 0.169 | E18: 0.375 | F18: 0.191 | G18: 0.393 | H18: 0.06 | I18: =IF(H18>0.1,"", IF(AND(H18<=0.1,H18>0.05),"*", IF(AND(H18<=0.05,H18>0.01),"**", IF(H18<=0.01,"***","")))) -> *
A19: (B) Information source: Radio news | B19: 0.626 | C19: 0.484 | D19: 0.653 | E19: 0.476 | F19: 0.64 | G19: 0.48 | H19: 0.371 | I19: =IF(H19>0.1,"", IF(AND(H19<=0.1,H19>0.05),"*", IF(AND(H19<=0.05,H19>0.01),"**", IF(H19<=0.01,"***",""))))
A20: (B) Information source: Internet | B20: 0.453 | C20: 0.498 | D20: 0.593 | E20: 0.492 | F20: 0.526 | G20: 0.5 | H20: <0,001 | I20: ***
A21: (B) Information source: Social media | B21: 0.436 | C21: 0.496 | D21: 0.572 | E21: 0.495 | F21: 0.506 | G21: 0.5 | H21: <0,001 | I21: ***
A22: (B) Interest in politics (high vs low) | B22: 0.391 | C22: 0.489 | D22: 0.299 | E22: 0.458 | F22: 0.343 | G22: 0.475 | H22: 0.002 | I22: =IF(H22>0.1,"", IF(AND(H22<=0.1,H22>0.05),"*", IF(AND(H22<=0.05,H22>0.01),"**", IF(H22<=0.01,"***","")))) -> ***
A23: (B) How much system allows people to have a say | B23: . | C23: . | D23: . | E23: . | F23: . | G23: .
A24: (B) Satisfaction with political system performance | B24: 0.514 | C24: 0.5 | D24: 0.533 | E24: 0.499 | F24: 0.524 | G24: 0.5 | H24: 0.556 | I24: =IF(H24>0.1,"", IF(AND(H24<=0.1,H24>0.05),"*", IF(AND(H24<=0.05,H24>0.01),"**", IF(H24<=0.01,"***",""))))
A25: (B) Having a democratic political system | B25: 0.861 | C25: 0.346 | D25: 0.866 | E25: 0.341 | F25: 0.864 | G25: 0.343 | H25: 0.839 | I25: =IF(H25>0.1,"", IF(AND(H25<=0.1,H25>0.05),"*", IF(AND(H25<=0.05,H25>0.01),"**", IF(H25<=0.01,"***",""))))
A26: (B) Importance of democracy | B26: 0.882 | C26: 0.323 | D26: 0.877 | E26: 0.329 | F26: 0.879 | G26: 0.326 | H26: 0.799 | I26: =IF(H26>0.1,"", IF(AND(H26<=0.1,H26>0.05),"*", IF(AND(H26<=0.05,H26>0.01),"**", IF(H26<=0.01,"***",""))))
A27: (B) Confidence: The Government | B27: 0.19 | C27: 0.393 | D27: 0.181 | E27: 0.386 | F27: 0.185 | G27: 0.389 | H27: 0.728 | I27: =IF(H27>0.1,"", IF(AND(H27<=0.1,H27>0.05),"*", IF(AND(H27<=0.05,H27>0.01),"**", IF(H27<=0.01,"***",""))))
A28: (B) Confidence: The Political Parties | B28: 0.045 | C28: 0.208 | D28: 0.051 | E28: 0.221 | F28: 0.048 | G28: 0.215 | H28: 0.649 | I28: =IF(H28>0.1,"", IF(AND(H28<=0.1,H28>0.05),"*", IF(AND(H28<=0.05,H28>0.01),"**", IF(H28<=0.01,"***",""))))
A29: (B) Confidence: Parliament | B29: 0.104 | C29: 0.305 | D29: 0.076 | E29: 0.266 | F29: 0.09 | G29: 0.286 | H29: 0.139 | I29: =IF(H29>0.1,"", IF(AND(H29<=0.1,H29>0.05),"*", IF(AND(H29<=0.05,H29>0.01),"**", IF(H29<=0.01,"***",""))))

Sheet Brazil
A1: Country: Brazil
B2: Male | D2: Female | F2: Total
B3: % | C3: Sd | D3: % | E3: Sd | F3: % | G3: Sd | H3: Test | I3: p-value
A4: N | B4: 276 | C4: 0.43328 | D4: 361 | E4: 0.56672 | F4: 637 | G4: 1
A5: (B) Political action: attending lawful/peaceful demonstrations | B5: 0.717 | C5: 0.451 | D5: 0.769 | E5: 0.422 | F5: 0.747 | G5: 0.435 | H5: 0.147 | I5: =IF(H5>0.1,"", IF(AND(H5<=0.1,H5>0.05),"*", IF(AND(H5<=0.05,H5>0.01),"**", IF(H5<=0.01,"***",""))))
A6: (B) Political action: Signing a petition | B6: 0.531 | C6: 0.5 | D6: 0.466 | E6: 0.5 | F6: 0.494 | G6: 0.5 | H6: 0.118 | I6: =IF(H6>0.1,"", IF(AND(H6<=0.1,H6>0.05),"*", IF(AND(H6<=0.05,H6>0.01),"**", IF(H6<=0.01,"***",""))))
A7: (B) Political action: joining in boycotts | B7: 0.9 | C7: 0.3 | D7: 0.929 | E7: 0.258 | F7: 0.916 | G7: 0.277 | H7: 0.234 | I7: =IF(H7>0.1,"", IF(AND(H7<=0.1,H7>0.05),"*", IF(AND(H7<=0.05,H7>0.01),"**", IF(H7<=0.01,"***",""))))
A8: (B) Active/Inactive membership: Political party | B8: 0.041 | C8: 0.198 | D8: 0.028 | E8: 0.166 | F8: 0.034 | G8: 0.181 | H8: 0.4 | I8: =IF(H8>0.1,"", IF(AND(H8<=0.1,H8>0.05),"*", IF(AND(H8<=0.05,H8>0.01),"**", IF(H8<=0.01,"***",""))))
A9: (B) Social activism: Contacting a government official | B9: 0.896 | C9: 0.306 | D9: 0.889 | E9: 0.315 | F9: 0.892 | G9: 0.311 | H9: 0.79 | I9: =IF(H9>0.1,"", IF(AND(H9<=0.1,H9>0.05),"*", IF(AND(H9<=0.05,H9>0.01),"**", IF(H9<=0.01,"***",""))))
A10: (B) Social activism: Donating to a group or campaign | B10: 0.662 | C10: 0.474 | D10: 0.592 | E10: 0.492 | F10: 0.622 | G10: 0.485 | H10: 0.083 | I10: =IF(H10>0.1,"", IF(AND(H10<=0.1,H10>0.05),"*", IF(AND(H10<=0.05,H10>0.01),"**", IF(H10<=0.01,"***","")))) -> *
A11: (B) Social activism: Encouraging others to take action | B11: 0.853 | C11: 0.355 | D11: 0.923 | E11: 0.268 | F11: 0.892 | G11: 0.31 | H11: 0.006 | I11: =IF(H11>0.1,"", IF(AND(H11<=0.1,H11>0.05),"*", IF(AND(H11<=0.05,H11>0.01),"**", IF(H11<=0.01,"***","")))) -> ***
A12: (B) Political action: joining unofficial strikes | B12: 0.792 | C12: 0.407 | D12: 0.821 | E12: 0.384 | F12: 0.808 | G12: 0.394 | H12: 0.362 | I12: =IF(H12>0.1,"", IF(AND(H12<=0.1,H12>0.05),"*", IF(AND(H12<=0.05,H12>0.01),"**", IF(H12<=0.01,"***",""))))
A13: (B) Membership: charitable/humanitarian organization | B13: 0.067 | C13: 0.251 | D13: 0.079 | E13: 0.271 | F13: 0.074 | G13: 0.262 | H13: 0.567 | I13: =IF(H13>0.1,"", IF(AND(H13<=0.1,H13>0.05),"*", IF(AND(H13<=0.05,H13>0.01),"**", IF(H13<=0.01,"***",""))))
A14: (B) Political actions online: Encouraging others to act | B14: 0.835 | C14: 0.372 | D14: 0.901 | E14: 0.299 | F14: 0.872 | G14: 0.334 | H14: 0.018 | I14: =IF(H14>0.1,"", IF(AND(H14<=0.1,H14>0.05),"*", IF(AND(H14<=0.05,H14>0.01),"**", IF(H14<=0.01,"***","")))) -> **
A15: (B) Political actions online: Searching information | B15: 0.625 | C15: 0.485 | D15: 0.691 | E15: 0.463 | F15: 0.663 | G15: 0.473 | H15: 0.092 | I15: =IF(H15>0.1,"", IF(AND(H15<=0.1,H15>0.05),"*", IF(AND(H15<=0.05,H15>0.01),"**", IF(H15<=0.01,"***","")))) -> *
A16: (B) Political actions online: Organizing activities/protests | B16: 0.933 | C16: 0.25 | D16: 0.96 | E16: 0.195 | F16: 0.949 | G16: 0.221 | H16: 0.138 | I16: =IF(H16>0.1,"", IF(AND(H16<=0.1,H16>0.05),"*", IF(AND(H16<=0.05,H16>0.01),"**", IF(H16<=0.01,"***",""))))
... A29: (B) Confidence: Parliament | B29: 0.149 | C29: 0.356 | D29: 0.166 | E29: 0.372 | F29: 0.158 | G29: 0.365 | H29: 0.566 | I29: =IF(H29>0.1,"", IF(AND(H29<=0.1,H29>0.05),"*", IF(AND(H29<=0.05,H29>0.01),"**", IF(H29<=0.01,"***",""))))

Sheet Chile
A1: Country: Chile
B2: Male | D2: Female | F2: Total
B3: % | C3: Sd | D3: % | E3: Sd | F3: % | G3: Sd | H3: Test | I3: p-value
A4: N | B4: 124 | C4: 0.46269 | D4: 144 | E4: 0.53731 | F4: 268 | G4: 1
A5: (B) Political action: attending lawful/peaceful demonstrations | B5: 0.74 | C5: 0.441 | D5: 0.756 | E5: 0.431 | F5: 0.748 | G5: 0.435 | H5: 0.773 | I5: =IF(H5>0.1,"", IF(AND(H5<=0.1,H5>0.05),"*", IF(AND(H5<=0.05,H5>0.01),"**", IF(H5<=0.01,"***",""))))
A6: (B) Political action: Signing a petition | B6: 0.9 | C6: 0.301 | D6: 0.884 | E6: 0.321 | F6: 0.891 | G6: 0.312 | H6: 0.683 | I6: =IF(H6>0.1,"", IF(AND(H6<=0.1,H6>0.05),"*", IF(AND(H6<=0.05,H6>0.01),"**", IF(H6<=0.01,"***",""))))
A7: (B) Political action: joining in boycotts | B7: 0.975 | C7: 0.157 | D7: 0.986 | E7: 0.12 | F7: 0.981 | G7: 0.138 | H7: 0.537 | I7: =IF(H7>0.1,"", IF(AND(H7<=0.1,H7>0.05),"*", IF(AND(H7<=0.05,H7>0.01),"**", IF(H7<=0.01,"***",""))))
A8: (B) Active/Inactive membership: Political party | B8: 0.153 | C8: 0.362 | D8: 0.125 | E8: 0.332 | F8: 0.138 | G8: 0.346 | H8: 0.506 | I8: =IF(H8>0.1,"", IF(AND(H8<=0.1,H8>0.05),"*", IF(AND(H8<=0.05,H8>0.01),"**", IF(H8<=0.01,"***",""))))
A9: (B) Social activism: Contacting a government official | B9: 0.942 | C9: 0.235 | D9: 0.912 | E9: 0.284 | F9: 0.926 | G9: 0.262 | H9: 0.373 | I9: =IF(H9>0.1,"", IF(AND(H9<=0.1,H9>0.05),"*", IF(AND(H9<=0.05,H9>0.01),"**", IF(H9<=0.01,"***",""))))
A10: (B) Social activism: Donating to a group or campaign | B10: 0.744 | C10: 0.438 | D10: 0.635 | E10: 0.483 | F10: 0.686 | G10: 0.465 | H10: 0.061 | I10: =IF(H10>0.1,"", IF(AND(H10<=0.1,H10>0.05),"*", IF(AND(H10<=0.05,H10>0.01),"**", IF(H10<=0.01,"***","")))) -> *
A11: (B) Social activism: Encouraging others to take action | B11: 0.913 | C11: 0.283 | D11: 0.876 | E11: 0.331 | F11: 0.893 | G11: 0.31 | H11: 0.344 | I11: =IF(H11>0.1,"", IF(AND(H11<=0.1,H11>0.05),"*", IF(AND(H11<=0.05,H11>0.01),"**", IF(H11<=0.01,"***",""))))
A12: (B) Political action: joining unofficial strikes | B12: 0.837 | C12: 0.371 | D12: 0.851 | E12: 0.358 | F12: 0.844 | G12: 0.363 | H12: 0.769 | I12: =IF(H12>0.1,"", IF(AND(H12<=0.1,H12>0.05),"*", IF(AND(H12<=0.05,H12>0.01),"**", IF(H12<=0.01,"***",""))))
A13: (B) Membership: charitable/humanitarian organization | B13: 0.145 | C13: 0.354 | D13: 0.132 | E13: 0.34 | F13: 0.138 | G13: 0.346 | H13: 0.756 | I13: =IF(H13>0.1,"", IF(AND(H13<=0.1,H13>0.05),"*", IF(AND(H13<=0.05,H13>0.01),"**", IF(H13<=0.01,"***",""))))
A14: (B) Political actions online: Encouraging others to act | B14: 0.897 | C14: 0.306 | D14: 0.926 | E14: 0.263 | F14: 0.912 | G14: 0.283 | H14: 0.414 | I14: =IF(H14>0.1,"", IF(AND(H14<=0.1,H14>0.05),"*", IF(AND(H14<=0.05,H14>0.01),"**", IF(H14<=0.01,"***",""))))
A15: (B) Political actions online: Searching information | B15: 0.782 | C15: 0.415 | D15: 0.743 | E15: 0.439 | F15: 0.761 | G15: 0.427 | H15: 0.47 | I15: =IF(H15>0.1,"", IF(AND(H15<=0.1,H15>0.05),"*", IF(AND(H15<=0.05,H15>0.01),"**", IF(H15<=0.01,"***",""))))
A16: (B) Political actions online: Organizing activities/protests | B16: 0.93 | C16: 0.257 | D16: 0.949 | E16: 0.222 | F16: 0.94 | G16: 0.238 | H16: 0.537 | I16: =IF(H16>0.1,"", IF(AND(H16<=0.1,H16>0.05),"*", IF(AND(H16<=0.05,H16>0.01),"**", IF(H16<=0.01,"***",""))))
... A22: (B) Interest in politics (high vs low) | B22: 0.266 | C22: 0.444 | D22: 0.237 | E22: 0.427 | F22: 0.251 | G22: 0.434 | H22: 0.593 | I22: =IF(H22>0.1,"", IF(AND(H22<=0.1,H22>0.05),"*", IF(AND(H22<=0.05,H22>0.01),"**", IF(H22<=0.01,"***",""))))
A23: (B) How much system allows people to have a say | B23: . | C23: . | D23: . | F23: . | G23: . | H23: .
A24: (B) Satisfaction with political system performance | B24: 0.479 | C24: 0.502 | D24: 0.467 | E24: 0.501 | F24: 0.472 | G24: 0.5 | H24: 0.856 | I24: =IF(H24>0.1,"", IF(AND(H24<=0.1,H24>0.05),"*", IF(AND(H24<=0.05,H24>0.01),"**", IF(H24<=0.01,"***",""))))
A25: (B) Having a democratic political system | B25: 0.865 | C25: 0.343 | D25: 0.894 | E25: 0.309 | F25: 0.881 | G25: 0.325 | H25: 0.488 | I25: =IF(H25>0.1,"", IF(AND(H25<=0.1,H25>0.05),"*", IF(AND(H25<=0.05,H25>0.01),"**", IF(H25<=0.01,"***",""))))
A26: (B) Importance of democracy | B26: 0.838 | C26: 0.37 | D26: 0.887 | E26: 0.318 | F26: 0.864 | G26: 0.343 | H26: 0.255 | I26: =IF(H26>0.1,"", IF(AND(H26<=0.1,H26>0.05),"*", IF(AND(H26<=0.05,H26>0.01),"**", IF(H26<=0.01,"***",""))))
A27: (B) Confidence: The Government | B27: 0.322 | C27: 0.469 | D27: 0.315 | E27: 0.466 | F27: 0.318 | G27: 0.467 | H27: 0.895 | I27: =IF(H27>0.1,"", IF(AND(H27<=0.1,H27>0.05),"*", IF(AND(H27<=0.05,H27>0.01),"**", IF(H27<=0.01,"***",""))))
A28: (B) Confidence: The Political Parties | B28: 0.177 | C28: 0.384 | D28: 0.156 | E28: 0.364 | F28: 0.166 | G28: 0.373 | H28: 0.642 | I28: =IF(H28>0.1,"", IF(AND(H28<=0.1,H28>0.05),"*", IF(AND(H28<=0.05,H28>0.01),"**", IF(H28<=0.01,"***",""))))
A29: (B) Confidence: Parliament | B29: 0.197 | C29: 0.399 | D29: 0.175 | E29: 0.381 | F29: 0.185 | G29: 0.389 | H29: 0.649 | I29: =IF(H29>0.1,"", IF(AND(H29<=0.1,H29>0.05),"*", IF(AND(H29<=0.05,H29>0.01),"**", IF(H29<=0.01,"***",""))))

Sheet Colombia
A1: Country: Colombia
B2: Male | D2: Female | F2: Total
B3: % | C3: Sd | D3: % | E3: Sd | F3: % | G3: Sd | H3: Test | I3: p-value
A4: N | B4: 351 | C4: 0.49091 | D4: 364 | E4: 0.50909 | F4: 715 | G4: 1
A5: (B) Political action: attending lawful/peaceful demonstrations | B5: 0.678 | C5: 0.468 | D5: 0.816 | E5: 0.388 | F5: 0.748 | G5: 0.434 | H5: <0,001 | I5: ***
A6: (B) Political action: Signing a petition | B6: 0.675 | C6: 0.469 | D6: 0.714 | E6: 0.452 | F6: 0.695 | G6: 0.461 | H6: 0.257 | I6: =IF(H6>0.1,"", IF(AND(H6<=0.1,H6>0.05),"*", IF(AND(H6<=0.05,H6>0.01),"**", IF(H6<=0.01,"***",""))))
A7: (B) Political action: joining in boycotts | B7: 0.726 | C7: 0.446 | D7: 0.799 | E7: 0.401 | F7: 0.764 | G7: 0.425 | H7: 0.022 | I7: =IF(H7>0.1,"", IF(AND(H7<=0.1,H7>0.05),"*", IF(AND(H7<=0.05,H7>0.01),"**", IF(H7<=0.01,"***","")))) -> **
A8: (B) Active/Inactive membership: Political party | B8: 0.251 | C8: 0.434 | D8: 0.283 | E8: 0.451 | F8: 0.267 | G8: 0.443 | H8: 0.331 | I8: =IF(H8>0.1,"", IF(AND(H8<=0.1,H8>0.05),"*", IF(AND(H8<=0.05,H8>0.01),"**", IF(H8<=0.01,"***",""))))
A9: (B) Social activism: Contacting a government official | B9: 0.726 | C9: 0.446 | D9: 0.665 | E9: 0.473 | F9: 0.695 | G9: 0.461 | H9: 0.074 | I9: =IF(H9>0.1,"", IF(AND(H9<=0.1,H9>0.05),"*", IF(AND(H9<=0.05,H9>0.01),"**", IF(H9<=0.01,"***","")))) -> *
A10: (B) Social activism: Donating to a group or campaign | B10: 0.43 | C10: 0.496 | D10: 0.462 | E10: 0.499 | F10: 0.446 | G10: 0.497 | H10: 0.4 | I10: =IF(H10>0.1,"", IF(AND(H10<=0.1,H10>0.05),"*", IF(AND(H10<=0.05,H10>0.01),"**", IF(H10<=0.01,"***",""))))
A11: (B) Social activism: Encouraging others to take action | B11: 0.88 | C11: 0.325 | D11: 0.912 | E11: 0.284 | F11: 0.897 | G11: 0.305 | H11: 0.164 | I11: =IF(H11>0.1,"", IF(AND(H11<=0.1,H11>0.05),"*", IF(AND(H11<=0.05,H11>0.01),"**", IF(H11<=0.01,"***",""))))
A12: (B) Political action: joining unofficial strikes | B12: 0.821 | C12: 0.384 | D12: 0.887 | E12: 0.317 | F12: 0.855 | G12: 0.353 | H12: 0.011 | I12: =IF(H12>0.1,"", IF(AND(H12<=0.1,H12>0.05),"*", IF(AND(H12<=0.05,H12>0.01),"**", IF(H12<=0.01,"***","")))) -> **
A13: (B) Membership: charitable/humanitarian organization | B13: 0.288 | C13: 0.453 | D13: 0.346 | E13: 0.476 | F13: 0.317 | G13: 0.466 | H13: 0.094 | I13: =IF(H13>0.1,"", IF(AND(H13<=0.1,H13>0.05),"*", IF(AND(H13<=0.05,H13>0.01),"**", IF(H13<=0.01,"***","")))) -> *
A14: (B) Political actions online: Encouraging others to act | B14: 0.85 | C14: 0.358 | D14: 0.909 | E14: 0.288 | F14: 0.88 | G14: 0.326 | H14: 0.017 | I14: =IF(H14>0.1,"", IF(AND(H14<=0.1,H14>0.05),"*", IF(AND(H14<=0.05,H14>0.01),"**", IF(H14<=0.01,"***","")))) -> **
A15: (B) Political actions online: Searching information | B15: 0.682 | C15: 0.466 | D15: 0.722 | E15: 0.449 | F15: 0.702 | G15: 0.458 | H15: 0.26 | I15: =IF(H15>0.1,"", IF(AND(H15<=0.1,H15>0.05),"*", IF(AND(H15<=0.05,H15>0.01),"**", IF(H15<=0.01,"***",""))))
A16: (B) Political actions online: Organizing activities/protests | B16: 0.917 | C16: 0.276 | D16: 0.94 | E16: 0.238 | F16: 0.929 | G16: 0.258 | H16: 0.249 | I16: =IF(H16>0.1,"", IF(AND(H16<=0.1,H16>0.05),"*", IF(AND(H16<=0.05,H16>0.01),"**", IF(H16<=0.01,"***",""))))
A17: (B) Information source: Daily newspaper | B17: 0.84 | C17: 0.367 | D17: 0.887 | E17: 0.317 | F17: 0.864 | G17: 0.343 | H17: 0.067 | I17: =IF(H17>0.1,"", IF(AND(H17<=0.1,H17>0.05),"*", IF(AND(H17<=0.05,H17>0.01),"**", IF(H17<=0.01,"***","")))) -> *
... A21: (B) Information source: Social media | B21: 0.282 | C21: 0.451 | D21: 0.275 | E21: 0.447 | F21: 0.278 | G21: 0.448 | H21: 0.827 | I21: =IF(H21>0.1,"", IF(AND(H21<=0.1,H21>0.05),"*", IF(AND(H21<=0.05,H21>0.01),"**", IF(H21<=0.01,"***",""))))
A22: (B) Interest in politics (high vs low) | B22: 0.413 | C22: 0.493 | D22: 0.264 | E22: 0.441 | F22: 0.337 | G22: 0.473 | H22: <0,001 | I22: ***
A23: (B) How much system allows people to have a say | B23: 0.411 | C23: 0.493 | D23: 0.325 | E23: 0.469 | F23: 0.367 | G23: 0.483 | H23: 0.035 | I23: =IF(H23>0.1,"", IF(AND(H23<=0.1,H23>0.05),"*", IF(AND(H23<=0.05,H23>0.01),"**", IF(H23<=0.01,"***","")))) -> **
A24: (B) Satisfaction with political system performance | B24: 0.231 | C24: 0.422 | D24: 0.223 | E24: 0.417 | F24: 0.227 | G24: 0.419 | H24: 0.793 | I24: =IF(H24>0.1,"", IF(AND(H24<=0.1,H24>0.05),"*", IF(AND(H24<=0.05,H24>0.01),"**", IF(H24<=0.01,"***",""))))
A25: (B) Having a democratic political system | B25: 0.795 | C25: 0.404 | D25: 0.758 | E25: 0.429 | F25: 0.776 | G25: 0.417 | H25: 0.241 | I25: =IF(H25>0.1,"", IF(AND(H25<=0.1,H25>0.05),"*", IF(AND(H25<=0.05,H25>0.01),"**", IF(H25<=0.01,"***",""))))
A26: (B) Importance of democracy | B26: 0.823 | C26: 0.382 | D26: 0.827 | E26: 0.379 | F26: 0.825 | G26: 0.38 | H26: 0.9 | I26: =IF(H26>0.1,"", IF(AND(H26<=0.1,H26>0.05),"*", IF(AND(H26<=0.05,H26>0.01),"**", IF(H26<=0.01,"***",""))))
A27: (B) Confidence: The Government | B27: 0.097 | C27: 0.296 | D27: 0.085 | E27: 0.28 | F27: 0.091 | G27: 0.288 | H27: 0.587 | I27: =IF(H27>0.1,"", IF(AND(H27<=0.1,H27>0.05),"*", IF(AND(H27<=0.05,H27>0.01),"**", IF(H27<=0.01,"***",""))))
A28: (B) Confidence: The Political Parties | B28: 0.043 | C28: 0.203 | D28: 0.055 | E28: 0.228 | F28: 0.049 | G28: 0.216 | H28: 0.45 | I28: =IF(H28>0.1,"", IF(AND(H28<=0.1,H28>0.05),"*", IF(AND(H28<=0.05,H28>0.01),"**", IF(H28<=0.01,"***",""))))
A29: (B) Confidence: Parliament | B29: 0.051 | C29: 0.221 | D29: 0.047 | E29: 0.211 | F29: 0.049 | G29: 0.216 | H29: 0.777 | I29: =IF(H29>0.1,"", IF(AND(H29<=0.1,H29>0.05),"*", IF(AND(H29<=0.05,H29>0.01),"**", IF(H29<=0.01,"***",""))))

Sheet Ecuador
A1: Country: Ecuador
B2: Male | D2: Female | F2: Total
B3: % | C3: Sd | D3: % | E3: Sd | F3: % | G3: Sd | H3: Test | I3: p-value
A4: N | B4: 252 | C4: 0.4728 | D4: 281 | E4: 0.5272 | F4: 533 | G4: 1
A5: (B) Political action: attending lawful/peaceful demonstrations | B5: 0.87 | C5: 0.336 | D5: 0.888 | E5: 0.315 | F5: 0.88 | G5: 0.325 | H5: 0.526 | I5: =IF(H5>0.1,"", IF(AND(H5<=0.1,H5>0.05),"*", IF(AND(H5<=0.05,H5>0.01),"**", IF(H5<=0.01,"***",""))))
A6: (B) Political action: Signing a petition | B6: 0.825 | C6: 0.381 | D6: 0.887 | E6: 0.317 | F6: 0.857 | G6: 0.35 | H6: 0.042 | I6: =IF(H6>0.1,"", IF(AND(H6<=0.1,H6>0.05),"*", IF(AND(H6<=0.05,H6>0.01),"**", IF(H6<=0.01,"***","")))) -> **
A7: (B) Political action: joining in boycotts | B7: 0.974 | C7: 0.159 | D7: 0.992 | E7: 0.089 | F7: 0.983 | G7: 0.128 | H7: 0.126 | I7: =IF(H7>0.1,"", IF(AND(H7<=0.1,H7>0.05),"*", IF(AND(H7<=0.05,H7>0.01),"**", IF(H7<=0.01,"***",""))))
A8: (B) Active/Inactive membership: Political party | B8: 0.156 | C8: 0.364 | D8: 0.082 | E8: 0.275 | F8: 0.117 | G8: 0.321 | H8: 0.008 | I8: =IF(H8>0.1,"", IF(AND(H8<=0.1,H8>0.05),"*", IF(AND(H8<=0.05,H8>0.01),"**", IF(H8<=0.01,"***","")))) -> ***
A9: (B) Social activism: Contacting a government official | B9: 0.779 | C9: 0.416 | D9: 0.824 | E9: 0.382 | F9: 0.803 | G9: 0.398 | H9: 0.199 | I9: =IF(H9>0.1,"", IF(AND(H9<=0.1,H9>0.05),"*", IF(AND(H9<=0.05,H9>0.01),"**", IF(H9<=0.01,"***",""))))
A10: (B) Social activism: Donating to a group or campaign | B10: 0.611 | C10: 0.488 | D10: 0.596 | E10: 0.492 | F10: 0.603 | G10: 0.49 | H10: 0.715 | I10: =IF(H10>0.1,"", IF(AND(H10<=0.1,H10>0.05),"*", IF(AND(H10<=0.05,H10>0.01),"**", IF(H10<=0.01,"***",""))))
A11: (B) Social activism: Encouraging others to take action | B11: 0.928 | C11: 0.259 | D11: 0.964 | E11: 0.187 | F11: 0.947 | G11: 0.225 | H11: 0.067 | I11: =IF(H11>0.1,"", IF(AND(H11<=0.1,H11>0.05),"*", IF(AND(H11<=0.05,H11>0.01),"**", IF(H11<=0.01,"***","")))) -> *
A12: (B) Political action: joining unofficial strikes | B12: 0.924 | C12: 0.266 | D12: 0.949 | E12: 0.219 | F12: 0.937 | G12: 0.243 | H12: 0.225 | I12: =IF(H12>0.1,"", IF(AND(H12<=0.1,H12>0.05),"*", IF(AND(H12<=0.05,H12>0.01),"**", IF(H12<=0.01,"***",""))))
A13: (B) Membership: charitable/humanitarian organization | B13: 0.193 | C13: 0.395 | D13: 0.124 | E13: 0.33 | F13: 0.156 | G13: 0.364 | H13: 0.03 | I13: =IF(H13>0.1,"", IF(AND(H13<=0.1,H13>0.05),"*", IF(AND(H13<=0.05,H13>0.01),"**", IF(H13<=0.01,"***","")))) -> **
A14: (B) Political actions online: Encouraging others to act | B14: 0.936 | C14: 0.246 | D14: 0.957 | E14: 0.204 | F14: 0.947 | G14: 0.225 | H14: 0.286 | I14: =IF(H14>0.1,"", IF(AND(H14<=0.1,H14>0.05),"*", IF(AND(H14<=0.05,H14>0.01),"**", IF(H14<=0.01,"***",""))))
A15: (B) Political actions online: Searching information | B15: 0.776 | C15: 0.418 | D15: 0.786 | E15: 0.411 | F15: 0.781 | G15: 0.414 | H15: 0.777 | I15: =IF(H15>0.1,"", IF(AND(H15<=0.1,H15>0.05),"*", IF(AND(H15<=0.05,H15>0.01),"**", IF(H15<=0.01,"***",""))))
A16: (B) Political actions online: Organizing activities/protests | B16: 0.956 | C16: 0.206 | D16: 0.986 | E16: 0.119 | F16: 0.972 | G16: 0.166 | H16: 0.041 | I16: =IF(H16>0.1,"", IF(AND(H16<=0.1,H16>0.05),"*", IF(AND(H16<=0.05,H16>0.01),"**", IF(H16<=0.01,"***","")))) -> **
A17: (B) Information source: Daily newspaper | B17: 0.756 | C17: 0.43 | D17: 0.807 | E17: 0.395 | F17: 0.783 | G17: 0.413 | H17: 0.154 | I17: =IF(H17>0.1,"", IF(AND(H17<=0.1,H17>0.05),"*", IF(AND(H17<=0.05,H17>0.01),"**", IF(H17<=0.01,"***",""))))
A18: (B) Information source: TV news | B18: 0.38 | C18: 0.486 | D18: 0.246 | E18: 0.431 | F18: 0.309 | G18: 0.462 | H18: <0,001 | I18: ***
A19: (B) Information source: Radio news | B19: 0.688 | C19: 0.464 | D19: 0.754 | E19: 0.432 | F19: 0.723 | G19: 0.448 | H19: 0.093 | I19: =IF(H19>0.1,"", IF(AND(H19<=0.1,H19>0.05),"*", IF(AND(H19<=0.05,H19>0.01),"**", IF(H19<=0.01,"***","")))) -> *
A20: (B) Information source: Internet | B20: 0.295 | C20: 0.457 | D20: 0.324 | E20: 0.469 | F20: 0.31 | G20: 0.463 | H20: 0.471 | I20: =IF(H20>0.1,"", IF(AND(H20<=0.1,H20>0.05),"*", IF(AND(H20<=0.05,H20>0.01),"**", IF(H20<=0.01,"***",""))))
A21: (B) Information source: Social media | B21: 0.223 | C21: 0.417 | D21: 0.278 | E21: 0.449 | F21: 0.252 | G21: 0.435 | H21: 0.149 | I21: =IF(H21>0.1,"", IF(AND(H21<=0.1,H21>0.05),"*", IF(AND(H21<=0.05,H21>0.01),"**", IF(H21<=0.01,"***",""))))
A22: (B) Interest in politics (high vs low) | B22: 0.438 | C22: 0.497 | D22: 0.342 | E22: 0.475 | F22: 0.387 | G22: 0.488 | H22: 0.022 | I22: =IF(H22>0.1,"", IF(AND(H22<=0.1,H22>0.05),"*", IF(AND(H22<=0.05,H22>0.01),"**", IF(H22<=0.01,"***","")))) -> **
A23: (B) How much system allows people to have a say | B23: . | C23: . | D23: . | E23: . | F23: . | G23: . | H23: . | I23: =IF(H23>0.1,"", IF(AND(H23<=0.1,H23>0.05),"*", IF(AND(H23<=0.05,H23>0.01),"**", IF(H23<=0.01,"***",""))))
A24: (B) Satisfaction with political system performance | B24: 0.466 | C24: 0.5 | D24: 0.484 | E24: 0.501 | F24: 0.476 | G24: 0.5 | H24: 0.681 | I24: =IF(H24>0.1,"", IF(AND(H24<=0.1,H24>0.05),"*", IF(AND(H24<=0.05,H24>0.01),"**", IF(H24<=0.01,"***",""))))
A25: (B) Having a democratic political system | B25: 0.805 | C25: 0.397 | D25: 0.836 | E25: 0.371 | F25: 0.821 | G25: 0.384 | H25: 0.36 | I25: =IF(H25>0.1,"", IF(AND(H25<=0.1,H25>0.05),"*", IF(AND(H25<=0.05,H25>0.01),"**", IF(H25<=0.01,"***",""))))
A26: (B) Importance of democracy | B26: 0.741 | C26: 0.439 | D26: 0.864 | E26: 0.344 | F26: 0.806 | G26: 0.396 | H26: <0,001 | I26: ***
A27: (B) Confidence: The Government | B27: 0.339 | C27: 0.474 | D27: 0.369 | E27: 0.483 | F27: 0.355 | G27: 0.479 | H27: 0.464 | I27: =IF(H27>0.1,"", IF(AND(H27<=0.1,H27>0.05),"*", IF(AND(H27<=0.05,H27>0.01),"**", IF(H27<=0.01,"***",""))))
A28: (B) Confidence: The Political Parties | B28: 0.179 | C28: 0.384 | D28: 0.216 | E28: 0.412 | F28: 0.198 | G28: 0.399 | H28: 0.294 | I28: =IF(H28>0.1,"", IF(AND(H28<=0.1,H28>0.05),"*", IF(AND(H28<=0.05,H28>0.01),"**", IF(H28<=0.01,"***",""))))
A29: (B) Confidence: Parliament | B29: 0.271 | C29: 0.445 | D29: 0.283 | E29: 0.451 | F29: 0.277 | G29: 0.448 | H29: 0.754 | I29: =IF(H29>0.1,"", IF(AND(H29<=0.1,H29>0.05),"*", IF(AND(H29<=0.05,H29>0.01),"**", IF(H29<=0.01,"***",""))))

Sheet Guatemala
A1: Country: Guatemala
B2: Male | D2: Female | F2: Total
B3: % | C3: Sd | D3: % | E3: Sd | F3: % | G3: Sd | H3: Test | I3: p-value
A4: N | B4: 385 | C4: 0.51197 | D4: 367 | E4: 0.48803 | F4: 752 | G4: 1
A5: (B) Political action: attending lawful/peaceful demonstrations | B5: 0.839 | C5: 0.368 | D5: 0.836 | E5: 0.371 | F5: 0.837 | G5: 0.369 | H5: 0.898 | I5: =IF(H5>0.1,"", IF(AND(H5<=0.1,H5>0.05),"*", IF(AND(H5<=0.05,H5>0.01),"**", IF(H5<=0.01,"***",""))))
A6: (B) Political action: Signing a petition | B6: 0.686 | C6: 0.465 | D6: 0.81 | E6: 0.393 | F6: 0.747 | G6: 0.435 | H6: <0,001 | I6: ***
A7: (B) Political action: joining in boycotts | B7: 0.949 | C7: 0.221 | D7: 0.972 | E7: 0.166 | F7: 0.96 | G7: 0.196 | H7: 0.113 | I7: =IF(H7>0.1,"", IF(AND(H7<=0.1,H7>0.05),"*", IF(AND(H7<=0.05,H7>0.01),"**", IF(H7<=0.01,"***",""))))
A8: (B) Active/Inactive membership: Political party | B8: 0.212 | C8: 0.41 | D8: 0.198 | E8: 0.399 | F8: 0.205 | G8: 0.404 | H8: 0.639 | I8: =IF(H8>0.1,"", IF(AND(H8<=0.1,H8>0.05),"*", IF(AND(H8<=0.05,H8>0.01),"**", IF(H8<=0.01,"***",""))))
A9: (B) Social activism: Contacting a government official | B9: 0.78 | C9: 0.415 | D9: 0.789 | E9: 0.409 | F9: 0.784 | G9: 0.412 | H9: 0.76 | I9: =IF(H9>0.1,"", IF(AND(H9<=0.1,H9>0.05),"*", IF(AND(H9<=0.05,H9>0.01),"**", IF(H9<=0.01,"***",""))))
A10: (B) Social activism: Donating to a group or campaign | B10: 0.508 | C10: 0.501 | D10: 0.58 | E10: 0.494 | F10: 0.543 | G10: 0.498 | H10: 0.05 | I10: =IF(H10>0.1,"", IF(AND(H10<=0.1,H10>0.05),"*", IF(AND(H10<=0.05,H10>0.01),"**", IF(H10<=0.01,"***","")))) -> **
A11: (B) Social activism: Encouraging others to take action | B11: 0.911 | C11: 0.286 | D11: 0.946 | E11: 0.226 | F11: 0.928 | G11: 0.259 | H11: 0.064 | I11: =IF(H11>0.1,"", IF(AND(H11<=0.1,H11>0.05),"*", IF(AND(H11<=0.05,H11>0.01),"**", IF(H11<=0.01,"***","")))) -> *
A12: (B) Political action: joining unofficial strikes | B12: 0.916 | C12: 0.278 | D12: 0.907 | E12: 0.291 | F12: 0.911 | G12: 0.284 | H12: 0.664 | I12: =IF(H12>0.1,"", IF(AND(H12<=0.1,H12>0.05),"*", IF(AND(H12<=0.05,H12>0.01),"**", IF(H12<=0.01,"***",""))))
A13: (B) Membership: charitable/humanitarian organization | B13: 0.348 | C13: 0.477 | D13: 0.333 | E13: 0.472 | F13: 0.341 | G13: 0.474 | H13: 0.685 | I13: =IF(H13>0.1,"", IF(AND(H13<=0.1,H13>0.05),"*", IF(AND(H13<=0.05,H13>0.01),"**", IF(H13<=0.01,"***",""))))
A14: (B) Political actions online: Encouraging others to act | B14: 0.87 | C14: 0.337 | D14: 0.878 | E14: 0.328 | F14: 0.874 | G14: 0.332 | H14: 0.739 | I14: =IF(H14>0.1,"", IF(AND(H14<=0.1,H14>0.05),"*", IF(AND(H14<=0.05,H14>0.01),"**", IF(H14<=0.01,"***",""))))
